[2022-05-12 07:14:26,325] {taskinstance.py:1159} INFO - Dependencies all met for <TaskInstance: live_stream_Dag.consumer_twitter_data manual__2022-05-12T07:14:24.929235+00:00 [queued]>
[2022-05-12 07:14:26,335] {taskinstance.py:1159} INFO - Dependencies all met for <TaskInstance: live_stream_Dag.consumer_twitter_data manual__2022-05-12T07:14:24.929235+00:00 [queued]>
[2022-05-12 07:14:26,338] {taskinstance.py:1356} INFO - 
--------------------------------------------------------------------------------
[2022-05-12 07:14:26,340] {taskinstance.py:1357} INFO - Starting attempt 1 of 2
[2022-05-12 07:14:26,341] {taskinstance.py:1358} INFO - 
--------------------------------------------------------------------------------
[2022-05-12 07:14:26,353] {taskinstance.py:1377} INFO - Executing <Task(BashOperator): consumer_twitter_data> on 2022-05-12 07:14:24.929235+00:00
[2022-05-12 07:14:26,359] {standard_task_runner.py:52} INFO - Started process 578 to run task
[2022-05-12 07:14:26,367] {standard_task_runner.py:79} INFO - Running: ['***', 'tasks', 'run', 'live_stream_Dag', 'consumer_twitter_data', 'manual__2022-05-12T07:14:24.929235+00:00', '--job-id', '3', '--raw', '--subdir', 'DAGS_FOLDER/live_stream_dag.py', '--cfg-path', '/tmp/tmpqs2rzl4f', '--error-file', '/tmp/tmpfwp36a8z']
[2022-05-12 07:14:26,369] {standard_task_runner.py:80} INFO - Job 3: Subtask consumer_twitter_data
[2022-05-12 07:14:26,432] {task_command.py:369} INFO - Running <TaskInstance: live_stream_Dag.consumer_twitter_data manual__2022-05-12T07:14:24.929235+00:00 [running]> on host 176cd38f3c0c
[2022-05-12 07:14:26,585] {taskinstance.py:1571} INFO - Exporting the following env vars:
AIRFLOW_CTX_DAG_OWNER=Airflow
AIRFLOW_CTX_DAG_ID=live_stream_Dag
AIRFLOW_CTX_TASK_ID=consumer_twitter_data
AIRFLOW_CTX_EXECUTION_DATE=2022-05-12T07:14:24.929235+00:00
AIRFLOW_CTX_TRY_NUMBER=1
AIRFLOW_CTX_DAG_RUN_ID=manual__2022-05-12T07:14:24.929235+00:00
[2022-05-12 07:14:26,586] {subprocess.py:62} INFO - Tmp dir root location: 
 /tmp
[2022-05-12 07:14:26,587] {subprocess.py:74} INFO - Running command: ['bash', '-c', 'python3 /opt/***/dags/consumer_tweets.py']
[2022-05-12 07:14:26,593] {subprocess.py:85} INFO - Output:
[2022-05-12 07:14:26,909] {subprocess.py:92} INFO - JAVA_HOME is not set
[2022-05-12 07:14:27,000] {subprocess.py:92} INFO - Traceback (most recent call last):
[2022-05-12 07:14:27,001] {subprocess.py:92} INFO -   File "/opt/***/dags/consumer_tweets.py", line 39, in <module>
[2022-05-12 07:14:27,002] {subprocess.py:92} INFO -     .config("spark.streaming.stopGracefullyOnShutdown", "true") \
[2022-05-12 07:14:27,004] {subprocess.py:92} INFO -   File "/home/***/.local/lib/python3.7/site-packages/pyspark/sql/session.py", line 228, in getOrCreate
[2022-05-12 07:14:27,005] {subprocess.py:92} INFO -     sc = SparkContext.getOrCreate(sparkConf)
[2022-05-12 07:14:27,005] {subprocess.py:92} INFO -   File "/home/***/.local/lib/python3.7/site-packages/pyspark/context.py", line 392, in getOrCreate
[2022-05-12 07:14:27,006] {subprocess.py:92} INFO -     SparkContext(conf=conf or SparkConf())
[2022-05-12 07:14:27,007] {subprocess.py:92} INFO -   File "/home/***/.local/lib/python3.7/site-packages/pyspark/context.py", line 144, in __init__
[2022-05-12 07:14:27,008] {subprocess.py:92} INFO -     SparkContext._ensure_initialized(self, gateway=gateway, conf=conf)
[2022-05-12 07:14:27,009] {subprocess.py:92} INFO -   File "/home/***/.local/lib/python3.7/site-packages/pyspark/context.py", line 339, in _ensure_initialized
[2022-05-12 07:14:27,010] {subprocess.py:92} INFO -     SparkContext._gateway = gateway or launch_gateway(conf)
[2022-05-12 07:14:27,011] {subprocess.py:92} INFO -   File "/home/***/.local/lib/python3.7/site-packages/pyspark/java_gateway.py", line 108, in launch_gateway
[2022-05-12 07:14:27,011] {subprocess.py:92} INFO -     raise RuntimeError("Java gateway process exited before sending its port number")
[2022-05-12 07:14:27,012] {subprocess.py:92} INFO - RuntimeError: Java gateway process exited before sending its port number
[2022-05-12 07:14:27,028] {subprocess.py:96} INFO - Command exited with return code 1
[2022-05-12 07:14:27,039] {taskinstance.py:1889} ERROR - Task failed with exception
Traceback (most recent call last):
  File "/home/airflow/.local/lib/python3.7/site-packages/airflow/operators/bash.py", line 195, in execute
    f'Bash command failed. The command returned a non-zero exit code {result.exit_code}.'
airflow.exceptions.AirflowException: Bash command failed. The command returned a non-zero exit code 1.
[2022-05-12 07:14:27,043] {taskinstance.py:1400} INFO - Marking task as UP_FOR_RETRY. dag_id=live_stream_Dag, task_id=consumer_twitter_data, execution_date=20220512T071424, start_date=20220512T071426, end_date=20220512T071427
[2022-05-12 07:14:27,050] {standard_task_runner.py:97} ERROR - Failed to execute job 3 for task consumer_twitter_data (Bash command failed. The command returned a non-zero exit code 1.; 578)
[2022-05-12 07:14:27,103] {local_task_job.py:156} INFO - Task exited with return code 1
[2022-05-12 07:14:27,124] {local_task_job.py:273} INFO - 0 downstream tasks scheduled from follow-on schedule check
